Workbook

Sheet Summary
A1: Chain Potential Score - Validated Chain Catalogue
A2: Every constituent finding was read from a completed Checkmarx One scan in tenant checkmarx-global-services-internal. Finding IDs are re-checkable via getFindingDetails(scan_id, finding_id). No chain contains a High or Critical finding.
A4: Chain ID | B4: Chain name | C4: Stack | D4: Findings | E4: Medium | F4: Low | G4: Info | H4: Chain CPS | I4: Band | J4: Source scan
A5: CH-101 | B5: Predictable Session to Account Takeover (PHP) | C5: PHP | D5: =COUNTIF(Traceability!$A:$A,$A5) -> 5 | E5: =COUNTIFS(Traceability!$A:$A,$A5,Traceability!$F:$F,"Medium") -> 3 | F5: =COUNTIFS(Traceability!$A:$A,$A5,Traceability!$F:$F,"Low") -> 2 | G5: =COUNTIFS(Traceability!$A:$A,$A5,Traceability!$F:$F,"Information") -> 0 | H5: 10 | I5: High | J5: c389b5e7-34fc-4be6-821b-59cd647c7f0b
A6: CH-102 | B6: Error-Leak to Credential Disclosure (Java) | C6: Java | D6: =COUNTIF(Traceability!$A:$A,$A6) -> 5 | E6: =COUNTIFS(Traceability!$A:$A,$A6,Traceability!$F:$F,"Medium") -> 3 | F6: =COUNTIFS(Traceability!$A:$A,$A6,Traceability!$F:$F,"Low") -> 2 | G6: =COUNTIFS(Traceability!$A:$A,$A6,Traceability!$F:$F,"Information") -> 0 | H6: 9.49 | I6: High | J6: 382c4fa6-5687-4b5a-8205-6ca91269c0fa
A7: CH-103 | B7: Config Tamper to Arbitrary File Write (Java) | C7: Java | D7: =COUNTIF(Traceability!$A:$A,$A7) -> 5 | E7: =COUNTIFS(Traceability!$A:$A,$A7,Traceability!$F:$F,"Medium") -> 3 | F7: =COUNTIFS(Traceability!$A:$A,$A7,Traceability!$F:$F,"Low") -> 2 | G7: =COUNTIFS(Traceability!$A:$A,$A7,Traceability!$F:$F,"Information") -> 0 | H7: 9.96 | I7: High | J7: 382c4fa6-5687-4b5a-8205-6ca91269c0fa
A8: CH-104 | B8: Redirect to Token Theft (JavaScript / Node) | C8: JavaScript / Node | D8: =COUNTIF(Traceability!$A:$A,$A8) -> 5 | E8: =COUNTIFS(Traceability!$A:$A,$A8,Traceability!$F:$F,"Medium") -> 2 | F8: =COUNTIFS(Traceability!$A:$A,$A8,Traceability!$F:$F,"Low") -> 3 | G8: =COUNTIFS(Traceability!$A:$A,$A8,Traceability!$F:$F,"Information") -> 0 | H8: 9.14 | I8: High | J8: b0fa38ca-d352-483a-9197-41f5e1dc0dec
A9: CH-105 | B9: Container Escape Surface (cross-engine: SAST + IaC) | C9: Docker / Compose | D9: =COUNTIF(Traceability!$A:$A,$A9) -> 5 | E9: =COUNTIFS(Traceability!$A:$A,$A9,Traceability!$F:$F,"Medium") -> 4 | F9: =COUNTIFS(Traceability!$A:$A,$A9,Traceability!$F:$F,"Low") -> 1 | G9: =COUNTIFS(Traceability!$A:$A,$A9,Traceability!$F:$F,"Information") -> 0 | H9: 9.25 | I9: High | J9: b0fa38ca-d352-483a-9197-41f5e1dc0dec
A10: CH-106 | B10: Informational-Only Chain to Silent Data Exfiltration | C10: Java | D10: =COUNTIF(Traceability!$A:$A,$A10) -> 5 | E10: =COUNTIFS(Traceability!$A:$A,$A10,Traceability!$F:$F,"Medium") -> 0 | F10: =COUNTIFS(Traceability!$A:$A,$A10,Traceability!$F:$F,"Low") -> 0 | G10: =COUNTIFS(Traceability!$A:$A,$A10,Traceability!$F:$F,"Information") -> 5 | H10: 9.15 | I10: High | J10: 382c4fa6-5687-4b5a-8205-6ca91269c0fa
A11: CH-107 | B11: Agent Tool-Path Error Disclosure (AI framework) | C11: Python / AI agent | D11: =COUNTIF(Traceability!$A:$A,$A11) -> 5 | E11: =COUNTIFS(Traceability!$A:$A,$A11,Traceability!$F:$F,"Medium") -> 1 | F11: =COUNTIFS(Traceability!$A:$A,$A11,Traceability!$F:$F,"Low") -> 4 | G11: =COUNTIFS(Traceability!$A:$A,$A11,Traceability!$F:$F,"Information") -> 0 | H11: 9.78 | I11: High | J11: 5797794c-4ea0-4553-a883-c908a6fec287
A12: CH-108 | B12: Defence-in-Depth Erosion to Credentialed Session Ride | C12: PHP | D12: =COUNTIF(Traceability!$A:$A,$A12) -> 5 | E12: =COUNTIFS(Traceability!$A:$A,$A12,Traceability!$F:$F,"Medium") -> 3 | F12: =COUNTIFS(Traceability!$A:$A,$A12,Traceability!$F:$F,"Low") -> 2 | G12: =COUNTIFS(Traceability!$A:$A,$A12,Traceability!$F:$F,"Information") -> 0 | H12: 9.24 | I12: High | J12: c389b5e7-34fc-4be6-821b-59cd647c7f0b
A13: CH-109 | B13: Cloud Exfiltration Blindness (Terraform / AWS) | C13: Terraform / AWS / K8s | D13: =COUNTIF(Traceability!$A:$A,$A13) -> 5 | E13: =COUNTIFS(Traceability!$A:$A,$A13,Traceability!$F:$F,"Medium") -> 5 | F13: =COUNTIFS(Traceability!$A:$A,$A13,Traceability!$F:$F,"Low") -> 0 | G13: =COUNTIFS(Traceability!$A:$A,$A13,Traceability!$F:$F,"Information") -> 0 | H13: 8.32 | I13: High | J13: b0b1dcd6-4cdc-4a3e-bb66-f689ec8e4999
A14: CH-110 | B14: API Auth Weakening to Token Forgery | C14: Go | D14: =COUNTIF(Traceability!$A:$A,$A14) -> 3 | E14: =COUNTIFS(Traceability!$A:$A,$A14,Traceability!$F:$F,"Medium") -> 2 | F14: =COUNTIFS(Traceability!$A:$A,$A14,Traceability!$F:$F,"Low") -> 1 | G14: =COUNTIFS(Traceability!$A:$A,$A14,Traceability!$F:$F,"Information") -> 0 | H14: 8.01 | I14: High | J14: 2e83d245-5417-4076-a24e-34622e6fd073
A15: CH-111 | B15: Cross-Site Forgery to Privileged State Change | C15: PHP | D15: =COUNTIF(Traceability!$A:$A,$A15) -> 4 | E15: =COUNTIFS(Traceability!$A:$A,$A15,Traceability!$F:$F,"Medium") -> 3 | F15: =COUNTIFS(Traceability!$A:$A,$A15,Traceability!$F:$F,"Low") -> 1 | G15: =COUNTIFS(Traceability!$A:$A,$A15,Traceability!$F:$F,"Information") -> 0 | H15: 7.65 | I15: High | J15: c389b5e7-34fc-4be6-821b-59cd647c7f0b
A16: CH-112 | B16: Error-Path Reconnaissance to Database Disclosure | C16: PHP | D16: =COUNTIF(Traceability!$A:$A,$A16) -> 4 | E16: =COUNTIFS(Traceability!$A:$A,$A16,Traceability!$F:$F,"Medium") -> 2 | F16: =COUNTIFS(Traceability!$A:$A,$A16,Traceability!$F:$F,"Low") -> 2 | G16: =COUNTIFS(Traceability!$A:$A,$A16,Traceability!$F:$F,"Information") -> 0 | H16: 8.62 | I16: High | J16: c389b5e7-34fc-4be6-821b-59cd647c7f0b
... A26: CH-122 | B26: Agent Session Replay | C26: Python / AI agent | D26: =COUNTIF(Traceability!$A:$A,$A26) -> 3 | E26: =COUNTIFS(Traceability!$A:$A,$A26,Traceability!$F:$F,"Medium") -> 1 | F26: =COUNTIFS(Traceability!$A:$A,$A26,Traceability!$F:$F,"Low") -> 2 | G26: =COUNTIFS(Traceability!$A:$A,$A26,Traceability!$F:$F,"Information") -> 0 | H26: 8.57 | I26: High | J26: 5797794c-4ea0-4553-a883-c908a6fec287
B27: TOTAL | D27: =SUM(D5:D26) -> 93 | E27: =SUM(E5:E26) -> 48 | F27: =SUM(F5:F26) -> 33 | G27: =SUM(G5:G26) -> 12 | I27: =COUNTIF(I5:I26,"High")&" of "&COUNTA(I5:I26)&" High band" -> 19 of 22 High band
A29: Constituent findings rated High or Critical: | E29: =COUNTIFS(Traceability!$F:$F,"High")+COUNTIFS(Traceability!$F:$F,"Critical") -> 0
A30: A finding may serve in more than one chain - that is composition, not duplication. The Findings sheet shows how many chains use each. Unique findings: see Findings sheet.

Sheet Traceability
A1: Chain-to-finding traceability matrix
A2: One row per chain participant. 'Checkmarx finding ID' + 'Scan ID' locate the finding in the Checkmarx One report; 'Location' locates it in source.
A4: Chain ID | B4: Chain name | C4: Stack | D4: Chain role | E4: Query name (as Checkmarx emits it) | F4: Severity | G4: Engine | H4: Individual CPS | I4: CPS band | J4: Project | K4: Scan ID | L4: Checkmarx finding ID | M4: Location (file:line)
A5: CH-101 | B5: Predictable Session to Account Takeover (PHP) | C5: PHP | D5: L2 Bridge | E5: Use of Insufficiently Random Values | F5: Medium | G5: SAST | H5: 7.75 | I5: High | J5: cx-andy-schmit/dvwa | K5: c389b5e7-34fc-4be6-821b-59cd647c7f0b | L5: 0cKWgAwBbW5DRBdAsAtFgWlDSps= | M5: /vulnerabilities/weak_id/index.php:17
A6: CH-101 | B6: Predictable Session to Account Takeover (PHP) | C6: PHP | D6: L2 Bridge | E6: Broken_or_Risky_Hashing_Function | F6: Medium | G6: SAST | H6: 7.12 | I6: Moderate | J6: cx-andy-schmit/dvwa | K6: c389b5e7-34fc-4be6-821b-59cd647c7f0b | L6: 1vhAEfdo6gX4o01jNtoWlL+5pFw= | M6: /vulnerabilities/brute/source/impossible.php:16
A7: CH-101 | B7: Predictable Session to Account Takeover (PHP) | C7: PHP | D7: L3 Amplifier | E7: Insecure_Value_of_the_SameSite_Cookie_Attribute | F7: Medium | G7: SAST | H7: 6.12 | I7: Moderate | J7: cx-andy-schmit/dvwa | K7: c389b5e7-34fc-4be6-821b-59cd647c7f0b | L7: 38KP0fXVsu0eaztrIE7FQMvcz3M= | M7: /vulnerabilities/weak_id/source/low.php:11
A8: CH-101 | B8: Predictable Session to Account Takeover (PHP) | C8: PHP | D8: L3 Amplifier | E8: Cookie_Overly_Broad_Path | F8: Low | G8: SAST | H8: 4.75 | I8: Low | J8: cx-andy-schmit/dvwa | K8: c389b5e7-34fc-4be6-821b-59cd647c7f0b | L8: fJwgEKiARdqTuc14ELI/eHWQNSE= | M8: /vulnerabilities/weak_id/source/low.php:11
A9: CH-101 | B9: Predictable Session to Account Takeover (PHP) | C9: PHP | D9: L1 Signal | E9: Use_of_Non_Cryptographic_Random | F9: Low | G9: SAST | H9: 7.75 | I9: High | J9: cx-andy-schmit/dvwa | K9: c389b5e7-34fc-4be6-821b-59cd647c7f0b | L9: 9nyPzW//SeMEwPhgCqv0U/sDuzg= | M9: /vulnerabilities/weak_id/source/impossible.php:6
A10: CH-102 | B10: Error-Leak to Credential Disclosure (Java) | C10: Java | D10: L2 Bridge | E10: Information_Exposure_Through_Query_String | F10: Medium | G10: SAST | H10: 7.12 | I10: Moderate | J10: cx-carolyn-yates/JavaVulnerableLab | K10: 382c4fa6-5687-4b5a-8205-6ca91269c0fa | L10: tgntZzrWo1jl7GbAn6d9U92okIU= | M10: /src/main/java/org/cysecurity/cspf/jvl/controller/Install.java:57
A11: CH-102 | B11: Error-Leak to Credential Disclosure (Java) | C11: Java | D11: L2 Bridge | E11: Exposure of Sensitive Information to an Unauthorized Actor | F11: Medium | G11: SAST | H11: 7.12 | I11: Moderate | J11: cx-carolyn-yates/JavaVulnerableLab | K11: 382c4fa6-5687-4b5a-8205-6ca91269c0fa | L11: odE2Z3LeAPVEmVcBoqlnC+wBjkc= | M11: /src/main/webapp/ForgotPassword.jsp:10
A12: CH-102 | B12: Error-Leak to Credential Disclosure (Java) | C12: Java | D12: L3 Amplifier | E12: Privacy_Violation | F12: Medium | G12: SAST | H12: 5.75 | I12: Moderate | J12: cx-carolyn-yates/JavaVulnerableLab | K12: 382c4fa6-5687-4b5a-8205-6ca91269c0fa | L12: qJaqS2qGP2h7Yg1/u45ItVUL1F0= | M12: /src/main/java/org/cysecurity/cspf/jvl/controller/XPathQuery.java:50
A13: CH-102 | B13: Error-Leak to Credential Disclosure (Java) | C13: Java | D13: L1 Signal | E13: Information_Exposure_Through_an_Error_Message | F13: Low | G13: SAST | H13: 6 | I13: Moderate | J13: cx-carolyn-yates/JavaVulnerableLab | K13: 382c4fa6-5687-4b5a-8205-6ca91269c0fa | L13: 467161 | M13: /src/main/java/org/cysecurity/cspf/jvl/controller/EmailCheck.java:60
A14: CH-102 | B14: Error-Leak to Credential Disclosure (Java) | C14: Java | D14: L1 Signal | E14: Heap_Inspection | F14: Low | G14: SAST | H14: 4.75 | I14: Low | J14: cx-carolyn-yates/JavaVulnerableLab | K14: 382c4fa6-5687-4b5a-8205-6ca91269c0fa | L14: 67831 | M14: /src/main/java/org/cysecurity/cspf/jvl/controller/LoginValidator.java:44
A15: CH-103 | B15: Config Tamper to Arbitrary File Write (Java) | C15: Java | D15: L2 Bridge | E15: External_Control_of_System_or_Config_Setting | F15: Medium | G15: SAST | H15: 7.5 | I15: Moderate | J15: cx-carolyn-yates/JavaVulnerableLab | K15: 382c4fa6-5687-4b5a-8205-6ca91269c0fa | L15: 117621 | M15: /src/main/java/org/cysecurity/cspf/jvl/controller/Install.java:57
A16: CH-103 | B16: Config Tamper to Arbitrary File Write (Java) | C16: Java | D16: L2 Bridge | E16: Parameter_Tampering | F16: Medium | G16: SAST | H16: 6.75 | I16: Moderate | J16: cx-carolyn-yates/JavaVulnerableLab | K16: 382c4fa6-5687-4b5a-8205-6ca91269c0fa | L16: oLhf1Sa69rpDxNtxDtYOlWclNgs= | M16: /src/main/java/org/cysecurity/cspf/jvl/controller/EmailCheck.java:42
... A25: CH-105 | B25: Container Escape Surface (cross-engine: SAST + IaC) | C25: Docker / Compose | D25: L2 Bridge | E25: Use_Of_Hardcoded_Password | F25: Medium | G25: SAST | H25: 6.5 | I25: Moderate | J25: OWASP/NodeGoat Demo | K25: b0fa38ca-d352-483a-9197-41f5e1dc0dec | L25: 6cZYX5Wlml3T9zR0xiuyTLYhFBI= | M25: /NodeGoat-master/artifacts/db-reset.js:27
A26: CH-105 | B26: Container Escape Surface (cross-engine: SAST + IaC) | C26: Docker / Compose | D26: L3 Amplifier | E26: Container Capabilities Unrestricted | F26: Medium | G26: IaC | H26: 7.25 | I26: Moderate | J26: OWASP/NodeGoat Demo | K26: b0fa38ca-d352-483a-9197-41f5e1dc0dec | L26: 6KfFKsfD633WAC53IIyANWDnYhg=
A27: CH-105 | B27: Container Escape Surface (cross-engine: SAST + IaC) | C27: Docker / Compose | D27: L3 Amplifier | E27: Security Opt Not Set | F27: Medium | G27: IaC | H27: 5.87 | I27: Moderate | J27: OWASP/NodeGoat Demo | K27: b0fa38ca-d352-483a-9197-41f5e1dc0dec | L27: 15674550
A28: CH-105 | B28: Container Escape Surface (cross-engine: SAST + IaC) | C28: Docker / Compose | D28: L3 Amplifier | E28: Container Traffic Not Bound To Host Interface | F28: Medium | G28: IaC | H28: 6.5 | I28: Moderate | J28: OWASP/NodeGoat Demo | K28: b0fa38ca-d352-483a-9197-41f5e1dc0dec | L28: 15674535
A29: CH-105 | B29: Container Escape Surface (cross-engine: SAST + IaC) | C29: Docker / Compose | D29: L1 Signal | E29: Healthcheck Instruction Missing | F29: Low | G29: IaC | H29: 1.12 | I29: Negligible | J29: OWASP/NodeGoat Demo | K29: b0fa38ca-d352-483a-9197-41f5e1dc0dec | L29: 15674561
A30: CH-106 | B30: Informational-Only Chain to Silent Data Exfiltration | C30: Java | D30: L2 Bridge | E30: Dynamic_SQL_Queries | F30: Information | G30: SAST | H30: 7.12 | I30: Moderate | J30: cx-carolyn-yates/JavaVulnerableLab | K30: 382c4fa6-5687-4b5a-8205-6ca91269c0fa | L30: 0XBp02QSHGEql4giNp73keCA3Es= | M30: /src/main/java/org/cysecurity/cspf/jvl/controller/LoginValidator.java:52
A31: CH-106 | B31: Informational-Only Chain to Silent Data Exfiltration | C31: Java | D31: L3 Amplifier | E31: Insufficient_Logging_of_Database_Actions | F31: Information | G31: SAST | H31: 5.12 | I31: Moderate | J31: cx-carolyn-yates/JavaVulnerableLab | K31: 382c4fa6-5687-4b5a-8205-6ca91269c0fa | L31: 12jj98OpDWTFsrU0lpG1XUagp/Y= | M31: /src/main/webapp/vulnerability/idor/change-email.jsp:32
A32: CH-106 | B32: Informational-Only Chain to Silent Data Exfiltration | C32: Java | D32: L2 Bridge | E32: Pages_Without_Global_Error_Handler | F32: Information | G32: SAST | H32: 5.75 | I32: Moderate | J32: cx-carolyn-yates/JavaVulnerableLab | K32: 382c4fa6-5687-4b5a-8205-6ca91269c0fa | L32: 0tZuTNbFjEN8ykwCCIAbRU3KNJA= | M32: /src/main/webapp/admin/admin.jsp:1
A33: CH-106 | B33: Informational-Only Chain to Silent Data Exfiltration | C33: Java | D33: L1 Signal | E33: Unchecked_Error_Condition | F33: Information | G33: SAST | H33: 4.75 | I33: Low | J33: cx-carolyn-yates/JavaVulnerableLab | K33: 382c4fa6-5687-4b5a-8205-6ca91269c0fa | L33: 3iWHH6gMkWJLKli9QiunyCCQIG0= | M33: /src/main/java/org/cysecurity/cspf/jvl/controller/Logout.java:42
A34: CH-106 | B34: Informational-Only Chain to Silent Data Exfiltration | C34: Java | D34: L1 Signal | E34: Use_of_System_Output_Stream | F34: Information | G34: SAST | H34: 4.62 | I34: Low | J34: cx-carolyn-yates/JavaVulnerableLab | K34: 382c4fa6-5687-4b5a-8205-6ca91269c0fa | L34: 0APbv9DRr/LUAZserU2/2fSPWus= | M34: /src/main/webapp/vulnerability/DisplayMessage.jsp:35
A35: CH-107 | B35: Agent Tool-Path Error Disclosure (AI framework) | C35: Python / AI agent | D35: L2 Bridge | E35: Object_Access_Violation | F35: Medium | G35: SAST | H35: 7.38 | I35: Moderate | J35: AISC_openai_agents_python | K35: 5797794c-4ea0-4553-a883-c908a6fec287 | L35: p9H+6K7MHD/gKWBQ699t5SEO4Pw= | M35: /src/agents/tool.py:1284
A36: CH-107 | B36: Agent Tool-Path Error Disclosure (AI framework) | C36: Python / AI agent | D36: L1 Signal | E36: Information_Exposure_Through_an_Error_Message | F36: Low | G36: SAST | H36: 6 | I36: Moderate | J36: AISC_openai_agents_python | K36: 5797794c-4ea0-4553-a883-c908a6fec287 | L36: gPZSEBzeEMW5I9wlkSoHqZvh4eQ= | M36: /src/agents/mcp/util.py:296
A37: CH-107 | B37: Agent Tool-Path Error Disclosure (AI framework) | C37: Python / AI agent | D37: L2 Bridge | E37: Information_Exposure_Through_an_Error_Message | F37: Low | G37: SAST | H37: 6 | I37: Moderate | J37: AISC_openai_agents_python | K37: 5797794c-4ea0-4553-a883-c908a6fec287 | L37: FRtCxgpOBDPuQtV+qNVxGbJ97BQ= | M37: /src/agents/run_internal/tool_actions.py:130
A38: CH-107 | B38: Agent Tool-Path Error Disclosure (AI framework) | C38: Python / AI agent | D38: L2 Bridge | E38: Information_Exposure_Through_an_Error_Message | F38: Low | G38: SAST | H38: 6 | I38: Moderate | J38: AISC_openai_agents_python | K38: 5797794c-4ea0-4553-a883-c908a6fec287 | L38: NwUJPu9T7HKfoPXIvLPqn011OpM= | M38: /src/agents/run_internal/session_persistence.py:479
A39: CH-107 | B39: Agent Tool-Path Error Disclosure (AI framework) | C39: Python / AI agent | D39: L1 Signal | E39: Information_Exposure_Through_an_Error_Message | F39: Low | G39: SAST | H39: 6 | I39: Moderate | J39: AISC_openai_agents_python | K39: 5797794c-4ea0-4553-a883-c908a6fec287 | L39: 32+Yo0mzZGU30FIJH3+Qi0oLngA= | M39: /src/agents/tracing/provider.py:95
A40: CH-108 | B40: Defence-in-Depth Erosion to Credentialed Session Ride | C40: PHP | D40: L2 Bridge | E40: CSRF | F40: Medium | G40: SAST | H40: 6.12 | I40: Moderate | J40: cx-andy-schmit/dvwa | K40: c389b5e7-34fc-4be6-821b-59cd647c7f0b | L40: 4BCo3G3gAni7aAzcVLnCbb++xpg= | M40: /vulnerabilities/captcha/source/low.php:50
A41: CH-108 | B41: Defence-in-Depth Erosion to Credentialed Session Ride | C41: PHP | D41: L2 Bridge | E41: Exposure of Sensitive Information to an Unauthorized Actor | F41: Medium | G41: SAST | H41: 7.12 | I41: Moderate | J41: cx-andy-schmit/dvwa | K41: c389b5e7-34fc-4be6-821b-59cd647c7f0b | L41: 3/YbcHdUmUIGhxgUr09l+gcwZ+Q= | M41: /dvwa/includes/DBMS/MySQL.php:88
... A84: CH-118 | B84: Reverse Tabnabbing to Session Capture | C84: JavaScript / Node | D84: L1 Signal | E84: Log_Forging | F84: Low | G84: SAST | H84: 5.25 | I84: Moderate | J84: OWASP/NodeGoat Demo | K84: b0fa38ca-d352-483a-9197-41f5e1dc0dec | L84: jV5Jfp7QHotJ/S1rIqQstuRJCZ8= | M84: /NodeGoat-master/app/routes/session.js:57
A85: CH-119 | B85: Unmonitored Container Exposure | C85: Docker | D85: L2 Bridge | E85: Container Traffic Not Bound To Host Interface | F85: Medium | G85: IaC | H85: 6.5 | I85: Moderate | J85: OWASP/NodeGoat Demo | K85: b0fa38ca-d352-483a-9197-41f5e1dc0dec | L85: 15674535
A86: CH-119 | B86: Unmonitored Container Exposure | C86: Docker | D86: L1 Signal | E86: Healthcheck Instruction Missing | F86: Low | G86: IaC | H86: 1.12 | I86: Negligible | J86: OWASP/NodeGoat Demo | K86: b0fa38ca-d352-483a-9197-41f5e1dc0dec | L86: 15674561
A87: CH-119 | B87: Unmonitored Container Exposure | C87: Docker | D87: L3 Amplifier | E87: Security Opt Not Set | F87: Medium | G87: IaC | H87: 5.87 | I87: Moderate | J87: OWASP/NodeGoat Demo | K87: b0fa38ca-d352-483a-9197-41f5e1dc0dec | L87: 15674550
A88: CH-119 | B88: Unmonitored Container Exposure | C88: Docker | D88: L3 Amplifier | E88: Log_Forging | F88: Low | G88: SAST | H88: 5.25 | I88: Moderate | J88: OWASP/NodeGoat Demo | K88: b0fa38ca-d352-483a-9197-41f5e1dc0dec | L88: jV5Jfp7QHotJ/S1rIqQstuRJCZ8= | M88: /NodeGoat-master/app/routes/session.js:57
A89: CH-120 | B89: Credentialed Image to Network Pivot | C89: Docker | D89: L2 Bridge | E89: Use_Of_Hardcoded_Password | F89: Medium | G89: SAST | H89: 6.5 | I89: Moderate | J89: OWASP/NodeGoat Demo | K89: b0fa38ca-d352-483a-9197-41f5e1dc0dec | L89: 6cZYX5Wlml3T9zR0xiuyTLYhFBI= | M89: /NodeGoat-master/artifacts/db-reset.js:27
A90: CH-120 | B90: Credentialed Image to Network Pivot | C90: Docker | D90: L3 Amplifier | E90: Container Capabilities Unrestricted | F90: Medium | G90: IaC | H90: 7.25 | I90: Moderate | J90: OWASP/NodeGoat Demo | K90: b0fa38ca-d352-483a-9197-41f5e1dc0dec | L90: 6KfFKsfD633WAC53IIyANWDnYhg=
A91: CH-120 | B91: Credentialed Image to Network Pivot | C91: Docker | D91: L3 Amplifier | E91: Container Traffic Not Bound To Host Interface | F91: Medium | G91: IaC | H91: 6.5 | I91: Moderate | J91: OWASP/NodeGoat Demo | K91: b0fa38ca-d352-483a-9197-41f5e1dc0dec | L91: 15674535
...

Sheet Findings
A1: Unique findings used across the catalogue
A2: Deduplicated by Checkmarx finding ID. 'Chains using' counts participation across the catalogue.
A4: Checkmarx finding ID | B4: Query name | C4: Severity | D4: Engine | E4: Individual CPS | F4: CPS band | G4: Project | H4: Scan ID | I4: Location (file:line) | J4: Chains using
A5: 0cKWgAwBbW5DRBdAsAtFgWlDSps= | B5: Use of Insufficiently Random Values | C5: Medium | D5: SAST | E5: 7.75 | F5: High | G5: cx-andy-schmit/dvwa | H5: c389b5e7-34fc-4be6-821b-59cd647c7f0b | I5: /vulnerabilities/weak_id/index.php:17 | J5: =COUNTIF(Traceability!$L:$L,$A5) -> 2
A6: 1vhAEfdo6gX4o01jNtoWlL+5pFw= | B6: Broken_or_Risky_Hashing_Function | C6: Medium | D6: SAST | E6: 7.12 | F6: Moderate | G6: cx-andy-schmit/dvwa | H6: c389b5e7-34fc-4be6-821b-59cd647c7f0b | I6: /vulnerabilities/brute/source/impossible.php:16 | J6: =COUNTIF(Traceability!$L:$L,$A6) -> 1
A7: 38KP0fXVsu0eaztrIE7FQMvcz3M= | B7: Insecure_Value_of_the_SameSite_Cookie_Attribute | C7: Medium | D7: SAST | E7: 6.12 | F7: Moderate | G7: cx-andy-schmit/dvwa | H7: c389b5e7-34fc-4be6-821b-59cd647c7f0b | I7: /vulnerabilities/weak_id/source/low.php:11 | J7: =COUNTIF(Traceability!$L:$L,$A7) -> 2
A8: fJwgEKiARdqTuc14ELI/eHWQNSE= | B8: Cookie_Overly_Broad_Path | C8: Low | D8: SAST | E8: 4.75 | F8: Low | G8: cx-andy-schmit/dvwa | H8: c389b5e7-34fc-4be6-821b-59cd647c7f0b | I8: /vulnerabilities/weak_id/source/low.php:11 | J8: =COUNTIF(Traceability!$L:$L,$A8) -> 3
A9: 9nyPzW//SeMEwPhgCqv0U/sDuzg= | B9: Use_of_Non_Cryptographic_Random | C9: Low | D9: SAST | E9: 7.75 | F9: High | G9: cx-andy-schmit/dvwa | H9: c389b5e7-34fc-4be6-821b-59cd647c7f0b | I9: /vulnerabilities/weak_id/source/impossible.php:6 | J9: =COUNTIF(Traceability!$L:$L,$A9) -> 2
A10: tgntZzrWo1jl7GbAn6d9U92okIU= | B10: Information_Exposure_Through_Query_String | C10: Medium | D10: SAST | E10: 7.12 | F10: Moderate | G10: cx-carolyn-yates/JavaVulnerableLab | H10: 382c4fa6-5687-4b5a-8205-6ca91269c0fa | I10: /src/main/java/org/cysecurity/cspf/jvl/controller/Install.java:57 | J10: =COUNTIF(Traceability!$L:$L,$A10) -> 2
A11: odE2Z3LeAPVEmVcBoqlnC+wBjkc= | B11: Exposure of Sensitive Information to an Unauthorized Actor | C11: Medium | D11: SAST | E11: 7.12 | F11: Moderate | G11: cx-carolyn-yates/JavaVulnerableLab | H11: 382c4fa6-5687-4b5a-8205-6ca91269c0fa | I11: /src/main/webapp/ForgotPassword.jsp:10 | J11: =COUNTIF(Traceability!$L:$L,$A11) -> 1
A12: qJaqS2qGP2h7Yg1/u45ItVUL1F0= | B12: Privacy_Violation | C12: Medium | D12: SAST | E12: 5.75 | F12: Moderate | G12: cx-carolyn-yates/JavaVulnerableLab | H12: 382c4fa6-5687-4b5a-8205-6ca91269c0fa | I12: /src/main/java/org/cysecurity/cspf/jvl/controller/XPathQuery.java:50 | J12: =COUNTIF(Traceability!$L:$L,$A12) -> 2
A13: 467161 | B13: Information_Exposure_Through_an_Error_Message | C13: Low | D13: SAST | E13: 6 | F13: Moderate | G13: cx-carolyn-yates/JavaVulnerableLab | H13: 382c4fa6-5687-4b5a-8205-6ca91269c0fa | I13: /src/main/java/org/cysecurity/cspf/jvl/controller/EmailCheck.java:60 | J13: =COUNTIF(Traceability!$L:$L,$A13) -> 2
A14: 67831 | B14: Heap_Inspection | C14: Low | D14: SAST | E14: 4.75 | F14: Low | G14: cx-carolyn-yates/JavaVulnerableLab | H14: 382c4fa6-5687-4b5a-8205-6ca91269c0fa | I14: /src/main/java/org/cysecurity/cspf/jvl/controller/LoginValidator.java:44 | J14: =COUNTIF(Traceability!$L:$L,$A14) -> 2
A15: 117621 | B15: External_Control_of_System_or_Config_Setting | C15: Medium | D15: SAST | E15: 7.5 | F15: Moderate | G15: cx-carolyn-yates/JavaVulnerableLab | H15: 382c4fa6-5687-4b5a-8205-6ca91269c0fa | I15: /src/main/java/org/cysecurity/cspf/jvl/controller/Install.java:57 | J15: =COUNTIF(Traceability!$L:$L,$A15) -> 2
A16: oLhf1Sa69rpDxNtxDtYOlWclNgs= | B16: Parameter_Tampering | C16: Medium | D16: SAST | E16: 6.75 | F16: Moderate | G16: cx-carolyn-yates/JavaVulnerableLab | H16: 382c4fa6-5687-4b5a-8205-6ca91269c0fa | I16: /src/main/java/org/cysecurity/cspf/jvl/controller/EmailCheck.java:42 | J16: =COUNTIF(Traceability!$L:$L,$A16) -> 2
... A25: 6cZYX5Wlml3T9zR0xiuyTLYhFBI= | B25: Use_Of_Hardcoded_Password | C25: Medium | D25: SAST | E25: 6.5 | F25: Moderate | G25: OWASP/NodeGoat Demo | H25: b0fa38ca-d352-483a-9197-41f5e1dc0dec | I25: /NodeGoat-master/artifacts/db-reset.js:27 | J25: =COUNTIF(Traceability!$L:$L,$A25) -> 2
A26: 6KfFKsfD633WAC53IIyANWDnYhg= | B26: Container Capabilities Unrestricted | C26: Medium | D26: IaC | E26: 7.25 | F26: Moderate | G26: OWASP/NodeGoat Demo | H26: b0fa38ca-d352-483a-9197-41f5e1dc0dec | J26: =COUNTIF(Traceability!$L:$L,$A26) -> 2
A27: 15674550 | B27: Security Opt Not Set | C27: Medium | D27: IaC | E27: 5.87 | F27: Moderate | G27: OWASP/NodeGoat Demo | H27: b0fa38ca-d352-483a-9197-41f5e1dc0dec | J27: =COUNTIF(Traceability!$L:$L,$A27) -> 2
A28: 15674535 | B28: Container Traffic Not Bound To Host Interface | C28: Medium | D28: IaC | E28: 6.5 | F28: Moderate | G28: OWASP/NodeGoat Demo | H28: b0fa38ca-d352-483a-9197-41f5e1dc0dec | J28: =COUNTIF(Traceability!$L:$L,$A28) -> 3
A29: 15674561 | B29: Healthcheck Instruction Missing | C29: Low | D29: IaC | E29: 1.12 | F29: Negligible | G29: OWASP/NodeGoat Demo | H29: b0fa38ca-d352-483a-9197-41f5e1dc0dec | J29: =COUNTIF(Traceability!$L:$L,$A29) -> 2
A30: 0XBp02QSHGEql4giNp73keCA3Es= | B30: Dynamic_SQL_Queries | C30: Information | D30: SAST | E30: 7.12 | F30: Moderate | G30: cx-carolyn-yates/JavaVulnerableLab | H30: 382c4fa6-5687-4b5a-8205-6ca91269c0fa | I30: /src/main/java/org/cysecurity/cspf/jvl/controller/LoginValidator.java:52 | J30: =COUNTIF(Traceability!$L:$L,$A30) -> 1
A31: 12jj98OpDWTFsrU0lpG1XUagp/Y= | B31: Insufficient_Logging_of_Database_Actions | C31: Information | D31: SAST | E31: 5.12 | F31: Moderate | G31: cx-carolyn-yates/JavaVulnerableLab | H31: 382c4fa6-5687-4b5a-8205-6ca91269c0fa | I31: /src/main/webapp/vulnerability/idor/change-email.jsp:32 | J31: =COUNTIF(Traceability!$L:$L,$A31) -> 3
A32: 0tZuTNbFjEN8ykwCCIAbRU3KNJA= | B32: Pages_Without_Global_Error_Handler | C32: Information | D32: SAST | E32: 5.75 | F32: Moderate | G32: cx-carolyn-yates/JavaVulnerableLab | H32: 382c4fa6-5687-4b5a-8205-6ca91269c0fa | I32: /src/main/webapp/admin/admin.jsp:1 | J32: =COUNTIF(Traceability!$L:$L,$A32) -> 2
A33: 3iWHH6gMkWJLKli9QiunyCCQIG0= | B33: Unchecked_Error_Condition | C33: Information | D33: SAST | E33: 4.75 | F33: Low | G33: cx-carolyn-yates/JavaVulnerableLab | H33: 382c4fa6-5687-4b5a-8205-6ca91269c0fa | I33: /src/main/java/org/cysecurity/cspf/jvl/controller/Logout.java:42 | J33: =COUNTIF(Traceability!$L:$L,$A33) -> 3
A34: 0APbv9DRr/LUAZserU2/2fSPWus= | B34: Use_of_System_Output_Stream | C34: Information | D34: SAST | E34: 4.62 | F34: Low | G34: cx-carolyn-yates/JavaVulnerableLab | H34: 382c4fa6-5687-4b5a-8205-6ca91269c0fa | I34: /src/main/webapp/vulnerability/DisplayMessage.jsp:35 | J34: =COUNTIF(Traceability!$L:$L,$A34) -> 3
A35: p9H+6K7MHD/gKWBQ699t5SEO4Pw= | B35: Object_Access_Violation | C35: Medium | D35: SAST | E35: 7.38 | F35: Moderate | G35: AISC_openai_agents_python | H35: 5797794c-4ea0-4553-a883-c908a6fec287 | I35: /src/agents/tool.py:1284 | J35: =COUNTIF(Traceability!$L:$L,$A35) -> 2
A36: gPZSEBzeEMW5I9wlkSoHqZvh4eQ= | B36: Information_Exposure_Through_an_Error_Message | C36: Low | D36: SAST | E36: 6 | F36: Moderate | G36: AISC_openai_agents_python | H36: 5797794c-4ea0-4553-a883-c908a6fec287 | I36: /src/agents/mcp/util.py:296 | J36: =COUNTIF(Traceability!$L:$L,$A36) -> 1
A37: FRtCxgpOBDPuQtV+qNVxGbJ97BQ= | B37: Information_Exposure_Through_an_Error_Message | C37: Low | D37: SAST | E37: 6 | F37: Moderate | G37: AISC_openai_agents_python | H37: 5797794c-4ea0-4553-a883-c908a6fec287 | I37: /src/agents/run_internal/tool_actions.py:130 | J37: =COUNTIF(Traceability!$L:$L,$A37) -> 1
A38: NwUJPu9T7HKfoPXIvLPqn011OpM= | B38: Information_Exposure_Through_an_Error_Message | C38: Low | D38: SAST | E38: 6 | F38: Moderate | G38: AISC_openai_agents_python | H38: 5797794c-4ea0-4553-a883-c908a6fec287 | I38: /src/agents/run_internal/session_persistence.py:479 | J38: =COUNTIF(Traceability!$L:$L,$A38) -> 2
A39: 32+Yo0mzZGU30FIJH3+Qi0oLngA= | B39: Information_Exposure_Through_an_Error_Message | C39: Low | D39: SAST | E39: 6 | F39: Moderate | G39: AISC_openai_agents_python | H39: 5797794c-4ea0-4553-a883-c908a6fec287 | I39: /src/agents/tracing/provider.py:95 | J39: =COUNTIF(Traceability!$L:$L,$A39) -> 2
A40: 4BCo3G3gAni7aAzcVLnCbb++xpg= | B40: CSRF | C40: Medium | D40: SAST | E40: 6.12 | F40: Moderate | G40: cx-andy-schmit/dvwa | H40: c389b5e7-34fc-4be6-821b-59cd647c7f0b | I40: /vulnerabilities/captcha/source/low.php:50 | J40: =COUNTIF(Traceability!$L:$L,$A40) -> 2
A41: 3/YbcHdUmUIGhxgUr09l+gcwZ+Q= | B41: Exposure of Sensitive Information to an Unauthorized Actor | C41: Medium | D41: SAST | E41: 7.12 | F41: Moderate | G41: cx-andy-schmit/dvwa | H41: c389b5e7-34fc-4be6-821b-59cd647c7f0b | I41: /dvwa/includes/DBMS/MySQL.php:88 | J41: =COUNTIF(Traceability!$L:$L,$A41) -> 2
... A52: d8VLX0/ssa9zVdKaddCJrd6Lklo= | B52: JWT_No_Claims_Directives_Validation | C52: Low | D52: SAST | E52: 6.12 | F52: Moderate | G52: cx-jeremy-polansky/authlab-canary | H52: 2e83d245-5417-4076-a24e-34622e6fd073 | I52: /app/controllers/app.go:396 | J52: =COUNTIF(Traceability!$L:$L,$A52) -> 1
A53: Unique findings | E53: =COUNTA(A5:A52) -> 48 | J53: =SUM(J5:J52) -> 93

Sheet Scans
A1: Source scan provenance
A2: Tenant: checkmarx-global-services-internal. All scans completed; findings read via the Checkmarx MCP on 2026-08-01.
A4: Project | B4: Scan ID | C4: Stack | D4: Scan totals (C / H / M / L / Info) | E4: Findings used | F4: Chains sourced
A5: cx-andy-schmit/dvwa | B5: c389b5e7-34fc-4be6-821b-59cd647c7f0b | C5: PHP | D5: 410 total - 59 C, 104 H, 86 M, 45 L, 116 Info | E5: =COUNTIFS(Findings!$G:$G,$A5) -> 10 | F5: =SUMPRODUCT((Traceability!$J$5:$J$97=$A5)/COUNTIFS(Traceability!$J$5:$J$97,Traceability!$J$5:$J$97,Traceability!$A$5:$A$97,Traceability!$A$5:$A$97)) -> 5
A6: cx-carolyn-yates/JavaVulnerableLab | B6: 382c4fa6-5687-4b5a-8205-6ca91269c0fa | C6: Java | D6: 860 total - 124 C, 119 H, 178 M, 133 L, 306 Info | E6: =COUNTIFS(Findings!$G:$G,$A6) -> 15 | F6: =SUMPRODUCT((Traceability!$J$5:$J$97=$A6)/COUNTIFS(Traceability!$J$5:$J$97,Traceability!$J$5:$J$97,Traceability!$A$5:$A$97,Traceability!$A$5:$A$97)) -> 7
A7: OWASP/NodeGoat Demo | B7: b0fa38ca-d352-483a-9197-41f5e1dc0dec | C7: JavaScript / Docker | D7: 687 total - 84 C, 300 H, 246 M, 55 L, 2 Info | E7: =COUNTIFS(Findings!$G:$G,$A7) -> 10 | F7: =SUMPRODUCT((Traceability!$J$5:$J$97=$A7)/COUNTIFS(Traceability!$J$5:$J$97,Traceability!$J$5:$J$97,Traceability!$A$5:$A$97,Traceability!$A$5:$A$97)) -> 5
A8: AISC_openai_agents_python | B8: 5797794c-4ea0-4553-a883-c908a6fec287 | C8: Python / AI agent | D8: 48 total - 16 C, 7 H, 1 M, 23 L, 1 Info | E8: =COUNTIFS(Findings!$G:$G,$A8) -> 5 | F8: =SUMPRODUCT((Traceability!$J$5:$J$97=$A8)/COUNTIFS(Traceability!$J$5:$J$97,Traceability!$J$5:$J$97,Traceability!$A$5:$A$97,Traceability!$A$5:$A$97)) -> 2
A9: owasp-juice-lab | B9: b0b1dcd6-4cdc-4a3e-bb66-f689ec8e4999 | C9: Terraform / AWS / K8s | D9: 55 total - 3 C, 12 H, 16 M, 15 L, 9 Info | E9: =COUNTIFS(Findings!$G:$G,$A9) -> 5 | F9: =SUMPRODUCT((Traceability!$J$5:$J$97=$A9)/COUNTIFS(Traceability!$J$5:$J$97,Traceability!$J$5:$J$97,Traceability!$A$5:$A$97,Traceability!$A$5:$A$97)) -> 2
A10: cx-jeremy-polansky/authlab-canary | B10: 2e83d245-5417-4076-a24e-34622e6fd073 | C10: Go | D10: 57 total - 12 C, 24 H, 17 M, 4 L | E10: =COUNTIFS(Findings!$G:$G,$A10) -> 3 | F10: =SUMPRODUCT((Traceability!$J$5:$J$97=$A10)/COUNTIFS(Traceability!$J$5:$J$97,Traceability!$J$5:$J$97,Traceability!$A$5:$A$97,Traceability!$A$5:$A$97)) -> 1
A12: The 'Scan totals' column is the argument: a severity-ordered backlog reaches these chains only after clearing every Critical and High above them. For the Informational-only chain (CH-106) that means clearing all 554 Critical/High/Medium/Low findings first.

Sheet Method
A1: Method, scoring model and verification
A4: Scoring model
A5: Each finding is scored 0-4 on five dimensions, weighted, then normalised to 0-10.
A6: Dimension | B6: Weight
A7: Prevalence | B7: 0.15
A8: Chain Utility | B8: 0.3
A9: AI Leverage | B9: 0.25
A10: Blast Radius | B10: 0.15
A11: Impact Proximity | B11: 0.15
A13: Per-finding CPS | B13: (10/4) x weighted sum of the five dimension scores
A14: Chain CPS | B14: max(individual scores) + 0.1 x sum(remaining scores), capped at 10.0
A15: Bands | B15: 0-2.5 Negligible | 2.6-5.0 Low | 5.1-7.5 Moderate | 7.6-10.0 High
A17: Method
A18: 1. Survey | B18: Query inventory read live from the tenant across PHP, Java, JavaScript, Go and Python presets, plus KICS and SCA.
A19: 2. Select | B19: Chains assembled only from findings that already existed, at the severity Checkmarx had already assigned. No prediction step.
A20: 3. Score | B20: Five-dimension rubric, aggregated by the chain formula above.
A21: 4. Verify | B21: Each chain re-matched against its own scan's findings. A guard test fails the build if any High or Critical enters a chain. A negative control confirms each fixture assembles only its own chains.
A23: Verification
A24: Automated tests | B24: 36 covering parser shapes, scorer dispatch, chain assembly, path scoping and the no-High guard.
A25: Re-check any row | B25: getFindingDetails(scan_id, finding_id) using the Traceability sheet columns K and L.
A27: Notes on composition
A28: Shared findings | B28: A finding may participate in several chains. Composition, not duplication - the Findings sheet counts participation.
A29: Moderate-band chains | B29: Three chains land in the Moderate band rather than High. They are retained deliberately: the framework grades chains, it does not assert that every chain is critical.
A30: Severity is preset-dependent | B30: The same query can carry different severities in different language presets - e.g. Use of Insufficiently Random Values is Medium in PHP and Low in JavaScript. Severity is bound to (query, language).
A31: Query names vary | B31: Casing and wording vary across presets and even within one scan. Matching requires normalisation.

Sheet Specimen Reproduction
A1: Nexa Commerce - single-codebase reproduction
A2: The chains above were observed across six separate applications. Nexa Commerce is a purpose-built polyglot e-commerce specimen intended to reproduce them in one repository. Status below is from scan cc434dd7 (repo github.com/cxsmtp/CPS-DEMO, commit 1a27a7d, v1).
A4: Chain | B4: Query reproduced | C4: Severity observed | D4: Location in specimen | E4: Status
A5: CH-101 | B5: Insecure_Value_of_the_SameSite_Cookie_Attribute | C5: Medium | D5: storefront/public/cart.php:25 | E5: Reproduced
A6: CH-101 | B6: Cookie_Overly_Broad_Path | C6: Low | D6: storefront/public/cart.php:25 | E6: Reproduced
A7: CH-102 | B7: Information_Exposure_Through_an_Error_Message | C7: Low | D7: catalog-service/.../CatalogServlet.java:34 | E7: Reproduced
A8: CH-103 | B8: External_Control_of_System_or_Config_Setting | C8: Medium | D8: catalog-service/.../ConfigServlet.java:44 | E8: Reproduced
A9: CH-103 | B9: Creation_of_Temp_File_With_Insecure_Permissions | C9: Low | D9: catalog-service/.../ReportBuilder.java:59 | E9: Reproduced (query name differs from source scan)
A10: CH-104 | B10: Open_Redirect | C10: Medium | D10: web-gateway/src/server.js:86 | E10: Reproduced
A11: CH-104 | B11: Log_Forging | C11: Low | D11: web-gateway/src/server.js:69, 85 | E11: Reproduced
A12: CH-105 | B12: Use_Of_Hardcoded_Password | C12: Medium | D12: ops/seed/seed.js:15 | E12: Reproduced
A13: CH-110 | B13: Client_Weak_Cryptographic_Hash | C13: Medium | D13: auth-service/public/js/checkout.js:54 | E13: Reproduced
A15: Reproduced in v1 | B15: 9 of 48 constituent findings, each at the predicted severity in the predicted file.
A16: Defects found in v1 | B16: Two, both in the specimen and both fixed in v2: a Critical Stored_XSS from streaming a template file to the HTTP response, and a High Plain_Text_Transport_Layer_in_Server from a non-TLS Go listener.
A17: Cause of misses (1) | B17: Python used str.format() where the reference framework uses f-strings; Checkmarx taint tracking follows the f-string interpolation.
A18: Cause of misses (2) | B18: Java read input via request.getAttribute(), which is not a taint source. Corrected to request.getParameter().
A19: Cause of misses (3) | B19: PHP patterns sat in lib/ includes; in this tenant the PHP preset reports at the entry-point page, not inside the include.
A20: Status | B20: v2 patches written and packaged; awaiting push and re-scan.
